Workbook

Sheet Planilha1
A1: Linha | B1: De → Para | C1: Fases | D1: Comprimento (mi)
A2: L1 | B2: 800 → 802 | C2: 3 | D2: 0.488 | F2: =D2+D3+D4+D6 -> 14.01565
A3: L2 | B3: 802 → 806 | C3: 3 | D3: 0.32765
A4: L3 | B4: 806 → 808 | C4: 3 | D4: 6.1
A5: L4 | B5: 808 → 810 | C5: 1 | D5: 1.099
A6: L5 | B6: 808 → 812 | C6: 3 | D6: 7.1
A7: L6 | B7: 812 → 814 | C7: 3 | D7: 5.63
A8: L7 | B8: 814r → 850 | C8: 3 | D8: 0.00189
A9: L8 | B9: 816 → 818 | C9: 1 | D9: 0.32386
A10: L9 | B10: 816 → 824 | C10: 3 | D10: 1.93
A11: L10 | B11: 818 → 820 | C11: 1 | D11: 9.12
A12: L11 | B12: 820 → 822 | C12: 1 | D12: 2.6
A13: L12 | B13: 824 → 826 | C13: 1 | D13: 0.57386
A14: L13 | B14: 824 → 828 | C14: 3 | D14: 0.15909
... A33: L32 | B33: 888 → 890 | C33: 3 | D33: 2
F34: =SUM(D2:D33) -> 58.34066

Sheet Planilha2
A1: BUS A | B1: BUS B | C1: LENGTH (FT.) | D1: LENGTH(MI.) | E1: CONFIG. CODE
A2: 800 | B2: 802 | C2: 2580 | D2: =C2/5280 -> 0.48863636 | E2: 301 | Y2: Linha | Z2: Fases | AA2: Bus 1 | AB2: Bus 2 | AC2: LineCode | AD2: Comprimento (mi)
A3: 802 | B3: 806 | C3: 1730 | D3: =C3/5280 -> 0.32765152 | E3: 301 | G3: 812 | H3: 814 | I3: 29730 | J3: =I3/5280 -> 5.6306818 | K3: 301 | M3: =Y8 -> L6 | N3: 812 | O3: 814 | Q3: 5.6306818 | R3: =Q3/2.4039 -> 2.3423112 | S3: 301 | V3: Função Objetivo | W3: =P3+P4+P5+P6+P7+P8+P9+P10+P11+P12+P13+P14+P15+P16+P17+P18+P19+P20 -> 0 | Y3: L1 | Z3: 3 | AA3: 800.1.2.3 | AB3: 802.1.2.3 | AC3: 300 | AD3: 0.488
A4: 806 | B4: 808 | C4: 32230 | D4: =C4/5280 -> 6.1041667 | E4: 301 | G4: 814 | H4: 850 | I4: 10 | J4: =I4/5280 -> 0.0018939394 | K4: 301 | M4: =Y9 -> L7 | N4: 814 | O4: 850 | Q4: 0.0018939394 | R4: =Q4/2.4039 -> 0.00078786114 | S4: 301 | Y4: L2 | Z4: 3 | AA4: 802.1.2.3 | AB4: 806.1.2.3 | AC4: 300 | AD4: 0.32765
A5: 808 | B5: 810 | C5: 5840 | D5: =C5/5280 -> 1.1060606 | E5: 303 | G5: 850 | H5: 816 | I5: 310 | J5: =I5/5280 -> 0.058712121 | K5: 301 | M5: =Y26 -> L24 | N5: 850 | O5: 816 | Q5: 0.058712121 | R5: =Q5/2.4039 -> 0.024423695 | S5: 301 | Y5: L3 | Z5: 3 | AA5: 806.1.2.3 | AB5: 808.1.2.3 | AC5: 300 | AD5: 6.1
A6: 808 | B6: 812 | C6: 37500 | D6: =C6/5280 -> 7.1022727 | E6: 301 | G6: 816 | H6: 824 | I6: 10210 | J6: =I6/5280 -> 1.9337121 | K6: 301 | M6: =Y11 -> L9 | N6: 816 | O6: 824 | Q6: 1.9337121 | R6: =Q6/2.4039 -> 0.80440622 | S6: 301 | Y6: L4 | Z6: 1 | AA6: 808.2 | AB6: 810.2 | AC6: 303 | AD6: 1.099
A7: 812 | B7: 814 | C7: 29730 | D7: =C7/5280 -> 5.6306818 | E7: 301 | G7: 824 | H7: 828 | I7: 840 | J7: =I7/5280 -> 0.15909091 | K7: 301 | M7: =Y15 -> L13 | N7: 824 | O7: 828 | Q7: 0.15909091 | R7: =Q7/2.4039 -> 0.066180336 | S7: 301 | Y7: L5 | Z7: 3 | AA7: 808.1.2.3 | AB7: 812.1.2.3 | AC7: 300 | AD7: 7.1
A8: 814 | B8: 850 | C8: 10 | D8: =C8/5280 -> 0.0018939394 | E8: 301 | G8: 828 | H8: 830 | I8: 20440 | J8: =I8/5280 -> 3.8712121 | K8: 301 | M8: =Y16 -> L14 | N8: 828 | O8: 830 | Q8: 3.8712121 | R8: =Q8/2.4039 -> 1.6103882 | S8: 301 | Y8: L6 | Z8: 3 | AA8: 812.1.2.3 | AB8: 814.1.2.3 | AC8: 300 | AD8: 2.34
A9: 816 | B9: 818 | C9: 1710 | D9: =C9/5280 -> 0.32386364 | E9: 302 | G9: 830 | H9: 854 | I9: 520 | J9: =I9/5280 -> 0.098484848 | K9: 301 | M9: =Y17 -> L15 | N9: 830 | O9: 854 | Q9: 0.098484848 | R9: =Q9/2.4039 -> 0.040968779 | S9: 301 | W9: =22.91/9.53 -> 2.4039874 | Y9: L7 | Z9: 3 | AA9: 814r.1.2.3 | AB9: 850.1.2.3 | AC9: 301 | AD9: 0.0008
A10: 816 | B10: 824 | C10: 10210 | D10: =C10/5280 -> 1.9337121 | E10: 301 | G10: 854 | H10: 852 | I10: 36830 | J10: =I10/5280 -> 6.9753788 | K10: 301 | M10: =Y29 -> L27 | N10: 854 | O10: 852 | Q10: 6.9753788 | R10: =Q10/2.4039 -> 2.9016926 | S10: 301 | Y10: L8 | Z10: 1 | AA10: 816.1 | AB10: 818.1 | AC10: 302 | AD10: 0.32386
A11: 818 | B11: 820 | C11: 48150 | D11: =C11/5280 -> 9.1193182 | E11: 302 | G11: 852 | H11: 832 | I11: 10 | J11: =I11/5280 -> 0.0018939394 | K11: 301 | M11: =Y27 -> L25 | N11: 852 | O11: 832 | Q11: 0.0018939394 | R11: =Q11/2.4039 -> 0.00078786114 | S11: 301 | Y11: L9 | Z11: 3 | AA11: 816.1.2.3 | AB11: 824.1.2.3 | AC11: 301 | AD11: 0.8044
A12: 820 | B12: 822 | C12: 13740 | D12: =C12/5280 -> 2.6022727 | E12: 302 | G12: 832 | H12: 858 | I12: 4900 | J12: =I12/5280 -> 0.9280303 | K12: 301 | M12: =Y18 -> L16 | N12: 832 | O12: 858 | Q12: 0.9280303 | R12: =Q12/2.4039 -> 0.38605196 | S12: 301 | Y12: L10 | Z12: 1 | AA12: 818.1 | AB12: 820.1 | AC12: 302 | AD12: 9.12
A13: 824 | B13: 826 | C13: 3030 | D13: =C13/5280 -> 0.57386364 | E13: 303 | G13: 858 | H13: 834 | I13: 5830 | J13: =I13/5280 -> 1.1041667 | K13: 301 | M13: =Y31 -> L29 | N13: 858 | O13: 834 | Q13: 1.1041667 | R13: =Q13/2.4039 -> 0.45932304 | S13: 301 | Y13: L11 | Z13: 1 | AA13: 820.1 | AB13: 822.1 | AC13: 302 | AD13: 2.6
A14: 824 | B14: 828 | C14: 840 | D14: =C14/5280 -> 0.15909091 | E14: 301 | G14: 834 | H14: 860 | I14: 2020 | J14: =I14/5280 -> 0.38257576 | K14: 301 | M14: =Y19 -> L17 | N14: 834 | O14: 860 | Q14: 0.38257576 | R14: =Q14/2.4039 -> 0.15914795 | S14: 301 | Y14: L12 | Z14: 1 | AA14: 824.2 | AB14: 826.2 | AC14: 303 | AD14: 0.57386
A15: 828 | B15: 830 | C15: 20440 | D15: =C15/5280 -> 3.8712121 | E15: 301 | G15: 860 | H15: 836 | I15: 2680 | J15: =I15/5280 -> 0.50757576 | K15: 301 | M15: =Y32 -> L30 | N15: 860 | O15: 836 | Q15: 0.50757576 | R15: =Q15/2.4039 -> 0.21114679 | S15: 301 | Y15: L13 | Z15: 3 | AA15: 824.1.2.3 | AB15: 828.1.2.3 | AC15: 301 | AD15: 0.06104
A16: 830 | B16: 854 | C16: 520 | D16: =C16/5280 -> 0.098484848 | E16: 301 | G16: 836 | H16: 840 | I16: 860 | J16: =I16/5280 -> 0.16287879 | K16: 301 | M16: =Y21 -> L19 | N16: 836 | O16: 840 | Q16: 0.16287879 | R16: =Q16/2.4039 -> 0.067756058 | S16: 301 | Y16: L14 | Z16: 3 | AA16: 828.1.2.3 | AB16: 830.1.2.3 | AC16: 301 | AD16: 1.6104
A17: 832 | B17: 858 | C17: 4900 | D17: =C17/5280 -> 0.9280303 | E17: 301 | J17: =SUM(J3:J16) -> 21.816288 | M17: =Y20 -> L18 | N17: 834 | O17: 842 | Q17: 0.053030303 | R17: =Q17/2.4039 -> 0.022060112 | S17: 301 | Y17: L15 | Z17: 3 | AA17: 830.1.2.3 | AB17: 854.1.2.3 | AC17: 301 | AD17: 0.041
A18: 832 | B18: 888 | C18: 0 | D18: =C18/5280 -> 0 | E18: 55 | M18: =Y23 -> L21 | N18: 842 | O18: 844 | Q18: 0.25568182 | R18: =Q18/2.4039 -> 0.10636125 | S18: 301 | Y18: L16 | Z18: 3 | AA18: 832.1.2.3 | AB18: 858.1.2.3 | AC18: 301 | AD18: 0.3861
A19: 834 | B19: 860 | C19: 2020 | D19: =C19/5280 -> 0.38257576 | E19: 301 | M19: =Y24 -> L22 | N19: 844 | O19: 846 | Q19: 0.68939394 | R19: =Q19/2.4039 -> 0.28678145 | S19: 301 | Y19: L17 | Z19: 3 | AA19: 834.1.2.3 | AB19: 860.1.2.3 | AC19: 301 | AD19: 0.1591
A20: 834 | B20: 842 | C20: 280 | D20: =C20/5280 -> 0.053030303 | E20: 301 | M20: =Y25 -> L23 | N20: 846 | O20: 848 | Q20: 0.10037879 | R20: =Q20/2.4039 -> 0.04175664 | S20: 301 | Y20: L18 | Z20: 3 | AA20: 834.1.2.3 | AB20: 842.1.2.3 | AC20: 301 | AD20: 0.0221
A21: 836 | B21: 840 | C21: 860 | D21: =C21/5280 -> 0.16287879 | E21: 301 | G21: 812 | H21: 814 | I21: 29730 | J21: =I21/5280 -> 5.6306818 | K21: 301 | Q21: =SUM(Q3:Q20) -> 22.914773 | R21: =SUM(R3:R20) -> 9.5323319 | Y21: L19 | Z21: 3 | AA21: 836.1.2.3 | AB21: 840.1.2.3 | AC21: 301 | AD21: 0.0678
A22: 836 | B22: 862 | C22: 280 | D22: =C22/5280 -> 0.053030303 | E22: 301 | G22: 814 | H22: 850 | I22: 10 | J22: =I22/5280 -> 0.0018939394 | K22: 301 | Y22: L20 | Z22: 3 | AA22: 836.1.2.3 | AB22: 862.1.2.3 | AC22: 301 | AD22: 0.05303
A23: 842 | B23: 844 | C23: 1350 | D23: =C23/5280 -> 0.25568182 | E23: 301 | G23: 850 | H23: 816 | I23: 310 | J23: =I23/5280 -> 0.058712121 | K23: 301 | Y23: L21 | Z23: 3 | AA23: 842.1.2.3 | AB23: 844.1.2.3 | AC23: 301 | AD23: 0.1064
A24: 844 | B24: 846 | C24: 3640 | D24: =C24/5280 -> 0.68939394 | E24: 301 | G24: 816 | H24: 824 | I24: 10210 | J24: =I24/5280 -> 1.9337121 | K24: 301 | Y24: L22 | Z24: 3 | AA24: 844.1.2.3 | AB24: 846.1.2.3 | AC24: 301 | AD24: 0.2868
A25: 846 | B25: 848 | C25: 530 | D25: =C25/5280 -> 0.10037879 | E25: 301 | G25: 824 | H25: 828 | I25: 840 | J25: =I25/5280 -> 0.15909091 | K25: 301 | Y25: L23 | Z25: 3 | AA25: 846.1.2.3 | AB25: 848.1.2.3 | AC25: 301 | AD25: 0.0418
A26: 850 | B26: 816 | C26: 310 | D26: =C26/5280 -> 0.058712121 | E26: 301 | G26: 828 | H26: 830 | I26: 20440 | J26: =I26/5280 -> 3.8712121 | K26: 301 | Y26: L24 | Z26: 3 | AA26: 850.1.2.3 | AB26: 816.1.2.3 | AC26: 301 | AD26: 0.0244
A27: 852 | B27: 832 | C27: 10 | D27: =C27/5280 -> 0.0018939394 | E27: 301 | G27: 830 | H27: 854 | I27: 520 | J27: =I27/5280 -> 0.098484848 | K27: 301 | Y27: L25 | Z27: 3 | AA27: 852r.1.2.3 | AB27: 832.1.2.3 | AC27: 301 | AD27: 0.0008
A28: 854 | B28: 856 | C28: 23330 | D28: =C28/5280 -> 4.4185606 | E28: 303 | G28: 854 | H28: 852 | I28: 36830 | J28: =I28/5280 -> 6.9753788 | K28: 301 | Y28: L26 | Z28: 1 | AA28: 854.2 | AB28: 856.2 | AC28: 303 | AD28: 4.41856
A29: 854 | B29: 852 | C29: 36830 | D29: =C29/5280 -> 6.9753788 | E29: 301 | G29: 852 | H29: 832 | I29: 10 | J29: =I29/5280 -> 0.0018939394 | K29: 301 | Y29: L27 | Z29: 3 | AA29: 854.1.2.3 | AB29: 852.1.2.3 | AC29: 301 | AD29: 6.97537
A30: 858 | B30: 864 | C30: 1620 | D30: =C30/5280 -> 0.30681818 | E30: 302 | G30: 832 | H30: 858 | I30: 4900 | J30: =I30/5280 -> 0.9280303 | K30: 301 | Y30: L28 | Z30: 1 | AA30: 858.1 | AB30: 864.1 | AC30: 303 | AD30: 0.30681
A31: 858 | B31: 834 | C31: 5830 | D31: =C31/5280 -> 1.1041667 | E31: 301 | G31: 858 | H31: 834 | I31: 5830 | J31: =I31/5280 -> 1.1041667 | K31: 301 | Y31: L29 | Z31: 3 | AA31: 858.1.2.3 | AB31: 834.1.2.3 | AC31: 301 | AD31: 0.4593
A32: 860 | B32: 836 | C32: 2680 | D32: =C32/5280 -> 0.50757576 | E32: 301 | G32: 834 | H32: 842 | I32: 280 | J32: =I32/5280 -> 0.053030303 | K32: 301 | Y32: L30 | Z32: 3 | AA32: 860.1.2.3 | AB32: 836.1.2.3 | AC32: 301 | AD32: 0.2111
A33: 862 | B33: 838 | C33: 4860 | D33: =C33/5280 -> 0.92045455 | E33: 304 | G33: 842 | H33: 844 | I33: 1350 | J33: =I33/5280 -> 0.25568182 | K33: 301 | Y33: L31 | Z33: 1 | AA33: 862.2 | AB33: 838.2 | AC33: 304 | AD33: 0.92045
A34: 888 | B34: 890 | C34: 10560 | D34: =C34/5280 -> 2 | E34: 300 | G34: 844 | H34: 846 | I34: 3640 | J34: =I34/5280 -> 0.68939394 | K34: 301 | Y34: L32 | Z34: 3 | AA34: 888.1.2.3 | AB34: 890.1.2.3 | AC34: 300 | AD34: 2
C35: =SUM(C2:C34) -> 308150 | D35: =SUM(D2:D34) -> 58.361742 | G35: 846 | H35: 848 | I35: 530 | J35: =I35/5280 -> 0.10037879 | K35: 301
C36: =C35/5280 -> 58.361742 | J36: =SUM(J21:J35) -> 21.861742 | Q36: =SUM(Q21:Q35) -> 22.914773

Sheet Cargas Originais
B2: BUS | C2: PH-1 KW | D2: PH1- KVAR | E2: PH-2 KW | F2: PH2- KVAR | G2: PH-3 KW | H2: PH3- KVAR | I2: SOMA KW | J2: SOMA KVAR
B3: 860 | C3: 19.91 | D3: 15.94 | E3: 19.91 | F3: 15.94 | G3: 19.91 | H3: 15.94 | I3: =SUM(C3,E3,G3) -> 59.73 | J3: =SUM(D3+F3+H3) -> 47.82
B4: 840 | C4: 8.86 | D4: 7.09 | E4: 8.86 | F4: 7.09 | G4: 8.86 | H4: 7.09 | I4: =SUM(C4,E4,G4) -> 26.58 | J4: =SUM(D4+F4+H4) -> 21.27
B5: 844 | C5: 133.44 | D5: 106.83 | E5: 133.44 | F5: 106.83 | G5: 133.44 | H5: 106.83 | I5: =SUM(C5,E5,G5) -> 400.32 | J5: =SUM(D5+F5+H5) -> 320.49
B6: 848 | C6: 19.45 | D6: 15.57 | E6: 19.45 | F6: 15.57 | G6: 19.45 | H6: 15.57 | I6: =SUM(C6,E6,G6) -> 58.35 | J6: =SUM(D6+F6+H6) -> 46.71
B7: 890 | C7: 27 | D7: 21.62 | E7: 27 | F7: 21.62 | G7: 27 | H7: 21.62 | I7: =SUM(C7,E7,G7) -> 81 | J7: =SUM(D7+F7+H7) -> 64.86
B8: SOMA | C8: =SUM(C3:C7) -> 208.66 | D8: =SUM(D3:D7) -> 167.05 | E8: =SUM(E3:E7) -> 208.66 | F8: =SUM(F3:F7) -> 167.05 | G8: =SUM(G3:G7) -> 208.66 | H8: =SUM(H3:H7) -> 167.05
A10: BUS A | B10: BUS B | C10: PH-1 KW | D10: PH-1 KVAR | E10: PH-2 KW | F10: PH-2 KVAR | G10: PH-3 KW | H10: PH-3 KVAR
A11: 802 | B11: 806 | C11: 0 | D11: 0 | E11: 31.22 | F11: 16.14 | G11: 26.07 | H11: 13.48 | K11: Total Ph1 KW | L11: Total Ph1 KVAR | M11: Total Ph2 KW | N11: Total Ph2 KVAR | O11: Total Ph3 KW | P11: Total Ph3 KVAR
A12: 808 | B12: 810 | C12: 0 | D12: 0 | E12: 15.88 | F12: 8.21 | G12: 0 | H12: 0 | K12: =C8+C30 -> 492.82 | L12: =D8+D30 -> 313.94 | M12: =E8+E30 -> 415.85 | N12: =F8+F30 -> 274.16 | O12: =G8+G30 -> 431.11 | P12: =H8+H30 -> 282.06
A13: 818 | B13: 820 | C13: 33.9 | D13: 17.52 | E13: 0 | F13: 0 | G13: 0 | H13: 0
A14: 820 | B14: 822 | C14: 135.53 | D14: 70.07 | E14: 0 | F14: 0 | G14: 0 | H14: 0
A15: 816 | B15: 824 | C15: 0 | D15: 0 | E15: 0.39 | F15: 0.2 | G15: 0 | H15: 0 | K15: Potencia Aparente PH1 | M15: Potencia Aparente PH2 | O15: Potencia Aparente PH3
A16: 824 | B16: 826 | C16: 0 | D16: 0 | E16: 41.93 | F16: 21.68 | G16: 0 | H16: 0 | K16: =SQRT(K12*K12+L12*L12) -> 584.32001 | M16: =SQRT(M12*M12+N12*N12) -> 498.09128 | O16: =SQRT(O12*O12+P12*P12) -> 515.18315
A17: 824 | B17: 828 | C17: 0 | D17: 0 | E17: 0 | F17: 0 | G17: 2.78 | H17: 1.44 | K17: Corrente de Fase 1 | M17: Corrente de Fase 2 | O17: Corrente de Fase 3 | Q17: SOMA
A18: 828 | B18: 830 | C18: 6.18 | D18: 3.2 | E18: 0 | F18: 0 | G18: 0 | H18: 0 | K18: =K16/(SQRT(3)*24.9) -> 13.548487 | M18: =M16/(SQRT(3)*24.9) -> 11.549122 | O18: =O16/(SQRT(3)*24.9) -> 11.945427 | Q18: =K18+M18+O18 -> 37.043035
A19: 854 | B19: 856 | C19: 0 | D19: 0 | E19: 3.71 | F19: 1.92 | G19: 0 | H19: 0
A20: 832 | B20: 858 | C20: 6.68 | D20: 3.45 | E20: 1.08 | F20: 0.56 | G20: 5.35 | H20: 2.77
A21: 858 | B21: 864 | C21: 0.63 | D21: 0.33 | E21: 0 | F21: 0 | G21: 0 | H21: 0
A22: 858 | B22: 834 | C22: 3.99 | D22: 2.06 | E22: 12.55 | F22: 6.49 | G22: 12.82 | H22: 6.63
A23: 834 | B23: 860 | C23: 15.66 | D23: 8.09 | E23: 20.86 | F23: 10.78 | G23: 111.15 | H23: 57.46
A24: 860 | B24: 836 | C24: 27.37 | D24: 14.15 | E24: 10.55 | F24: 5.45 | G24: 42.05 | H24: 21.74
A25: 836 | B25: 840 | C25: 17.49 | D25: 9.04 | E25: 21.81 | F25: 11.27 | G25: 0 | H25: 0
A26: 862 | B26: 838 | C26: 27.61 | D26: 14.27 | E26: 0 | F26: 0 | G26: 0 | H26: 0
A27: 842 | B27: 844 | C27: 9.12 | D27: 4.71 | E27: 0 | F27: 0 | G27: 0 | H27: 0
A28: 844 | B28: 846 | C28: 0 | D28: 0 | E28: 24.59 | F28: 12.71 | G28: 22.23 | H28: 11.49
A29: 846 | B29: 848 | C29: 0 | D29: 0 | E29: 22.62 | F29: 11.7 | G29: 0 | H29: 0
C30: =SUM(C11:C29) -> 284.16 | D30: =SUM(D11:D29) -> 146.89 | E30: =SUM(E11:E29) -> 207.19 | F30: =SUM(F11:F29) -> 107.11 | G30: =SUM(G11:G29) -> 222.45 | H30: =SUM(H11:H29) -> 115.01
C31: =so -> #NAME?
A39: BUS A | B39: BUS B
A40: 802 | B40: 806
A41: 808 | B41: 810
A42: 818 | B42: 820
A43: 820 | B43: 822
A44: 816 | B44: 824
A45: 824 | B45: 826
A46: 824 | B46: 828
A47: 828 | B47: 830
A48: 854 | B48: 856
A49: 832 | B49: 858
...

Sheet Cargas Alteradas
B2: BUS | C2: PH-1 KW | D2: PH1- KVAR | E2: PH-2 KW | F2: PH2- KVAR | G2: PH-3 KW | H2: PH3- KVAR | I2: SOMA KW | J2: SOMA KVAR
B3: 860 | C3: =19.91*$M$5 -> 228.44897 | D3: =15.94*$M$5 -> 182.89687 | E3: =19.91*$M$5 -> 228.44897 | F3: =15.94*$M$5 -> 182.89687 | G3: =19.91*$M$5 -> 228.44897 | H3: =15.94*$M$5 -> 182.89687 | I3: =SUM(C3,E3,G3) -> 685.34692 | J3: =SUM(D3+F3+H3) -> 548.6906
B4: 840 | C4: =8.86*$M$5 -> 101.66037 | D4: =7.09*$M$5 -> 81.351242 | E4: =8.86*$M$5 -> 101.66037 | F4: =7.09*$M$5 -> 81.351242 | G4: =8.86*$M$5 -> 101.66037 | H4: =7.09*$M$5 -> 81.351242 | I4: =SUM(C4,E4,G4) -> 304.9811 | J4: =SUM(D4+F4+H4) -> 244.05373
B5: 844 | C5: =133.44*$M$5 -> 1531.1015 | D5: =106.83*$M$5 -> 1225.7762 | E5: =133.44*$M$5 -> 1531.1015 | F5: =106.83*$M$5 -> 1225.7762 | G5: =133.44*$M$5 -> 1531.1015 | H5: =106.83*$M$5 -> 1225.7762 | I5: =SUM(C5,E5,G5) -> 4593.3045 | J5: =SUM(D5+F5+H5) -> 3677.3286 | L5: Fator | M5: =425/37.04 -> 11.474082
B6: 848 | C6: =19.45*$M$5 -> 223.1709 | D6: =15.57*$M$5 -> 178.65146 | E6: =19.45*$M$5 -> 223.1709 | F6: =15.57*$M$5 -> 178.65146 | G6: =19.45*$M$5 -> 223.1709 | H6: =15.57*$M$5 -> 178.65146 | I6: =SUM(C6,E6,G6) -> 669.51269 | J6: =SUM(D6+F6+H6) -> 535.95437
B7: 890 | C7: =27*$M$5 -> 309.80022 | D7: =21.62*$M$5 -> 248.06965 | E7: =27*$M$5 -> 309.80022 | F7: =21.62*$M$5 -> 248.06965 | G7: =27*$M$5 -> 309.80022 | H7: =21.62*$M$5 -> 248.06965 | I7: =SUM(C7,E7,G7) -> 929.40065 | J7: =SUM(D7+F7+H7) -> 744.20896
B8: SOMA | C8: =SUM(C3:C7) -> 2394.182 | D8: =SUM(D3:D7) -> 1916.7454 | E8: =SUM(E3:E7) -> 2394.182 | F8: =SUM(F3:F7) -> 1916.7454 | G8: =SUM(G3:G7) -> 2394.182 | H8: =SUM(H3:H7) -> 1916.7454
A10: BUS A | B10: BUS B | C10: PH-1 KW | D10: PH-1 KVAR | E10: PH-2 KW | F10: PH-2 KVAR | G10: PH-3 KW | H10: PH-3 KVAR
A11: 802 | B11: 806 | C11: ='Cargas Originais'!C11*$M$5 -> 0 | D11: ='Cargas Originais'!D11*$M$5 -> 0 | E11: ='Cargas Originais'!E11*$M$5 -> 358.22084 | F11: ='Cargas Originais'!F11*$M$5 -> 185.19168 | G11: ='Cargas Originais'!G11*$M$5 -> 299.12932 | H11: ='Cargas Originais'!H11*$M$5 -> 154.67063
A12: 808 | B12: 810 | C12: ='Cargas Originais'!C12*$M$5 -> 0 | D12: ='Cargas Originais'!D12*$M$5 -> 0 | E12: ='Cargas Originais'!E12*$M$5 -> 182.20842 | F12: ='Cargas Originais'!F12*$M$5 -> 94.202214 | G12: ='Cargas Originais'!G12*$M$5 -> 0 | H12: ='Cargas Originais'!H12*$M$5 -> 0 | K12: Total Ph1 KW | L12: Total Ph1 KVAR | M12: Total Ph2 KW | N12: Total Ph2 KVAR | O12: Total Ph3 KW | P12: Total Ph3 KVAR
A13: 818 | B13: 820 | C13: ='Cargas Originais'!C13*$M$5 -> 388.97138 | D13: ='Cargas Originais'!D13*$M$5 -> 201.02592 | E13: ='Cargas Originais'!E13*$M$5 -> 0 | F13: ='Cargas Originais'!F13*$M$5 -> 0 | G13: ='Cargas Originais'!G13*$M$5 -> 0 | H13: ='Cargas Originais'!H13*$M$5 -> 0 | K13: =C8+C30 -> 5654.6571 | L13: =D8+D30 -> 3602.1733 | M13: =E8+E30 -> 4771.497 | N13: =F8+F30 -> 3145.7343 | O13: =G8+G30 -> 4946.5915 | P13: =H8+H30 -> 3236.3796
A14: 820 | B14: 822 | C14: ='Cargas Originais'!C14*$M$5 -> 1555.0823 | D14: ='Cargas Originais'!D14*$M$5 -> 803.98893 | E14: ='Cargas Originais'!E14*$M$5 -> 0 | F14: ='Cargas Originais'!F14*$M$5 -> 0 | G14: ='Cargas Originais'!G14*$M$5 -> 0 | H14: ='Cargas Originais'!H14*$M$5 -> 0
A15: 816 | B15: 824 | C15: ='Cargas Originais'!C15*$M$5 -> 0 | D15: ='Cargas Originais'!D15*$M$5 -> 0 | E15: ='Cargas Originais'!E15*$M$5 -> 4.474892 | F15: ='Cargas Originais'!F15*$M$5 -> 2.2948164 | G15: ='Cargas Originais'!G15*$M$5 -> 0 | H15: ='Cargas Originais'!H15*$M$5 -> 0
A16: 824 | B16: 826 | C16: ='Cargas Originais'!C16*$M$5 -> 0 | D16: ='Cargas Originais'!D16*$M$5 -> 0 | E16: ='Cargas Originais'!E16*$M$5 -> 481.10826 | F16: ='Cargas Originais'!F16*$M$5 -> 248.7581 | G16: ='Cargas Originais'!G16*$M$5 -> 0 | H16: ='Cargas Originais'!H16*$M$5 -> 0 | K16: Potencia Aparente PH1 | M16: Potencia Aparente PH2 | O16: Potencia Aparente PH3
A17: 824 | B17: 828 | C17: ='Cargas Originais'!C17*$M$5 -> 0 | D17: ='Cargas Originais'!D17*$M$5 -> 0 | E17: ='Cargas Originais'!E17*$M$5 -> 0 | F17: ='Cargas Originais'!F17*$M$5 -> 0 | G17: ='Cargas Originais'!G17*$M$5 -> 31.897948 | H17: ='Cargas Originais'!H17*$M$5 -> 16.522678 | K17: =SQRT(K13*K13+L13*L13) -> 6704.5358 | M17: =SQRT(M13*M13+N13*N13) -> 5715.1403 | O17: =SQRT(O13*O13+P13*P13) -> 5911.2537
A18: 828 | B18: 830 | C18: ='Cargas Originais'!C18*$M$5 -> 70.909827 | D18: ='Cargas Originais'!D18*$M$5 -> 36.717063 | E18: ='Cargas Originais'!E18*$M$5 -> 0 | F18: ='Cargas Originais'!F18*$M$5 -> 0 | G18: ='Cargas Originais'!G18*$M$5 -> 0 | H18: ='Cargas Originais'!H18*$M$5 -> 0 | K18: Corrente de Fase 1 | M18: Corrente de Fase 2 | O18: Corrente de Fase 3 | Q18: SOMA
A19: 854 | B19: 856 | C19: ='Cargas Originais'!C19*$M$5 -> 0 | D19: ='Cargas Originais'!D19*$M$5 -> 0 | E19: ='Cargas Originais'!E19*$M$5 -> 42.568844 | F19: ='Cargas Originais'!F19*$M$5 -> 22.030238 | G19: ='Cargas Originais'!G19*$M$5 -> 0 | H19: ='Cargas Originais'!H19*$M$5 -> 0 | K19: =K17/(SQRT(3)*24.9) -> 155.45645 | M19: =M17/(SQRT(3)*24.9) -> 132.51557 | O19: =O17/(SQRT(3)*24.9) -> 137.06281 | Q19: =K19+M19+O19 -> 425.03483
A20: 832 | B20: 858 | C20: ='Cargas Originais'!C20*$M$5 -> 76.646868 | D20: ='Cargas Originais'!D20*$M$5 -> 39.585583 | E20: ='Cargas Originais'!E20*$M$5 -> 12.392009 | F20: ='Cargas Originais'!F20*$M$5 -> 6.425486 | G20: ='Cargas Originais'!G20*$M$5 -> 61.386339 | H20: ='Cargas Originais'!H20*$M$5 -> 31.783207
A21: 858 | B21: 864 | C21: ='Cargas Originais'!C21*$M$5 -> 7.2286717 | D21: ='Cargas Originais'!D21*$M$5 -> 3.7864471 | E21: ='Cargas Originais'!E21*$M$5 -> 0 | F21: ='Cargas Originais'!F21*$M$5 -> 0 | G21: ='Cargas Originais'!G21*$M$5 -> 0 | H21: ='Cargas Originais'!H21*$M$5 -> 0
A22: 858 | B22: 834 | C22: ='Cargas Originais'!C22*$M$5 -> 45.781587 | D22: ='Cargas Originais'!D22*$M$5 -> 23.636609 | E22: ='Cargas Originais'!E22*$M$5 -> 143.99973 | F22: ='Cargas Originais'!F22*$M$5 -> 74.466793 | G22: ='Cargas Originais'!G22*$M$5 -> 147.09773 | H22: ='Cargas Originais'!H22*$M$5 -> 76.073164
A23: 834 | B23: 860 | C23: ='Cargas Originais'!C23*$M$5 -> 179.68413 | D23: ='Cargas Originais'!D23*$M$5 -> 92.825324 | E23: ='Cargas Originais'!E23*$M$5 -> 239.34935 | F23: ='Cargas Originais'!F23*$M$5 -> 123.6906 | G23: ='Cargas Originais'!G23*$M$5 -> 1275.3442 | H23: ='Cargas Originais'!H23*$M$5 -> 659.30076
A24: 860 | B24: 836 | C24: ='Cargas Originais'!C24*$M$5 -> 314.04563 | D24: ='Cargas Originais'!D24*$M$5 -> 162.35826 | E24: ='Cargas Originais'!E24*$M$5 -> 121.05157 | F24: ='Cargas Originais'!F24*$M$5 -> 62.533747 | G24: ='Cargas Originais'!G24*$M$5 -> 482.48515 | H24: ='Cargas Originais'!H24*$M$5 -> 249.44654
A25: 836 | B25: 840 | C25: ='Cargas Originais'!C25*$M$5 -> 200.6817 | D25: ='Cargas Originais'!D25*$M$5 -> 103.7257 | E25: ='Cargas Originais'!E25*$M$5 -> 250.24973 | F25: ='Cargas Originais'!F25*$M$5 -> 129.3129 | G25: ='Cargas Originais'!G25*$M$5 -> 0 | H25: ='Cargas Originais'!H25*$M$5 -> 0
A26: 862 | B26: 838 | C26: ='Cargas Originais'!C26*$M$5 -> 316.79941 | D26: ='Cargas Originais'!D26*$M$5 -> 163.73515 | E26: ='Cargas Originais'!E26*$M$5 -> 0 | F26: ='Cargas Originais'!F26*$M$5 -> 0 | G26: ='Cargas Originais'!G26*$M$5 -> 0 | H26: ='Cargas Originais'!H26*$M$5 -> 0
A27: 842 | B27: 844 | C27: ='Cargas Originais'!C27*$M$5 -> 104.64363 | D27: ='Cargas Originais'!D27*$M$5 -> 54.042927 | E27: ='Cargas Originais'!E27*$M$5 -> 0 | F27: ='Cargas Originais'!F27*$M$5 -> 0 | G27: ='Cargas Originais'!G27*$M$5 -> 0 | H27: ='Cargas Originais'!H27*$M$5 -> 0
A28: 844 | B28: 846 | C28: ='Cargas Originais'!C28*$M$5 -> 0 | D28: ='Cargas Originais'!D28*$M$5 -> 0 | E28: ='Cargas Originais'!E28*$M$5 -> 282.14768 | F28: ='Cargas Originais'!F28*$M$5 -> 145.83558 | G28: ='Cargas Originais'!G28*$M$5 -> 255.06884 | H28: ='Cargas Originais'!H28*$M$5 -> 131.8372
A29: 846 | B29: 848 | C29: ='Cargas Originais'!C29*$M$5 -> 0 | D29: ='Cargas Originais'!D29*$M$5 -> 0 | E29: ='Cargas Originais'!E29*$M$5 -> 259.54374 | F29: ='Cargas Originais'!F29*$M$5 -> 134.24676 | G29: ='Cargas Originais'!G29*$M$5 -> 0 | H29: ='Cargas Originais'!H29*$M$5 -> 0
B30: SOMA | C30: =SUM(C11:C29) -> 3260.4752 | D30: =SUM(D11:D29) -> 1685.4279 | E30: =SUM(E11:E29) -> 2377.3151 | F30: =SUM(F11:F29) -> 1228.9889 | G30: =SUM(G11:G29) -> 2552.4096 | H30: =SUM(H11:H29) -> 1319.6342

Sheet Planilha5
A1: BUS A | B1: BUS B | C1: PH-1 KW | D1: PH-1 KVAR | E1: SB KW | F1: SBKVAR | G1: RB KW | H1: RB KVAR | I1: PH-2 KW | J1: PH-2 KVAR | K1: SB KW | L1: SBKVAR | M1: RB KW | N1: RB KVAR | O1: PH-3 KW | P1: PH-3 KVAR | Q1: SB KW | R1: SBKVAR | S1: RB KW | T1: RB KVAR
A2: 802 | B2: 806 | C2: 0 | D2: 0 | E2: =C2/2 -> 0 | F2: =D2/2 -> 0 | G2: =E2 -> 0 | H2: =F2 -> 0 | I2: 358.22084 | J2: 185.19168 | K2: =I2/2 -> 179.11042 | L2: =J2/2 -> 92.595842 | M2: =K2 -> 179.11042 | N2: =L2 -> 92.595842 | O2: 299.12932 | P2: 154.67063 | Q2: =O2/2 -> 149.56466 | R2: =P2/2 -> 77.335313 | S2: =Q2 -> 149.56466 | T2: =R2/2 -> 38.667657
A3: 808 | B3: 810 | C3: 0 | D3: 0 | E3: =C3/2 -> 0 | F3: =D3/2 -> 0 | G3: =E3 -> 0 | H3: =F3 -> 0 | I3: 182.20842 | J3: 94.202214 | K3: =I3/2 -> 91.104212 | L3: =J3/2 -> 47.101107 | M3: =K3 -> 91.104212 | N3: =L3 -> 47.101107 | O3: 0 | P3: 0 | Q3: =O3/2 -> 0 | R3: =P3/2 -> 0 | S3: =Q3 -> 0 | T3: =R3/2 -> 0
A4: 818 | B4: 820 | C4: 388.97138 | D4: 201.02592 | E4: =C4/2 -> 194.48569 | F4: =D4/2 -> 100.51296 | G4: =E4 -> 194.48569 | H4: =F4 -> 100.51296 | I4: 0 | J4: 0 | K4: =I4/2 -> 0 | L4: =J4/2 -> 0 | M4: =K4 -> 0 | N4: =L4 -> 0 | O4: 0 | P4: 0 | Q4: =O4/2 -> 0 | R4: =P4/2 -> 0 | S4: =Q4 -> 0 | T4: =R4/2 -> 0
A5: 820 | B5: 822 | C5: 1555.0823 | D5: 803.98893 | E5: =C5/2 -> 777.54117 | F5: =D5/2 -> 401.99447 | G5: =E5 -> 777.54117 | H5: =F5 -> 401.99447 | I5: 0 | J5: 0 | K5: =I5/2 -> 0 | L5: =J5/2 -> 0 | M5: =K5 -> 0 | N5: =L5 -> 0 | O5: 0 | P5: 0 | Q5: =O5/2 -> 0 | R5: =P5/2 -> 0 | S5: =Q5 -> 0 | T5: =R5/2 -> 0
A6: 816 | B6: 824 | C6: 0 | D6: 0 | E6: =C6/2 -> 0 | F6: =D6/2 -> 0 | G6: =E6 -> 0 | H6: =F6 -> 0 | I6: 4.474892 | J6: 2.2948164 | K6: =I6/2 -> 2.237446 | L6: =J6/2 -> 1.1474082 | M6: =K6 -> 2.237446 | N6: =L6 -> 1.1474082 | O6: 0 | P6: 0 | Q6: =O6/2 -> 0 | R6: =P6/2 -> 0 | S6: =Q6 -> 0 | T6: =R6/2 -> 0
A7: 824 | B7: 826 | C7: 0 | D7: 0 | E7: =C7/2 -> 0 | F7: =D7/2 -> 0 | G7: =E7 -> 0 | H7: =F7 -> 0 | I7: 481.10826 | J7: 248.7581 | K7: =I7/2 -> 240.55413 | L7: =J7/2 -> 124.37905 | M7: =K7 -> 240.55413 | N7: =L7 -> 124.37905 | O7: 0 | P7: 0 | Q7: =O7/2 -> 0 | R7: =P7/2 -> 0 | S7: =Q7 -> 0 | T7: =R7/2 -> 0
A8: 824 | B8: 828 | C8: 0 | D8: 0 | E8: =C8/2 -> 0 | F8: =D8/2 -> 0 | G8: =E8 -> 0 | H8: =F8 -> 0 | I8: 0 | J8: 0 | K8: =I8/2 -> 0 | L8: =J8/2 -> 0 | M8: =K8 -> 0 | N8: =L8 -> 0 | O8: 31.897948 | P8: 16.522678 | Q8: =O8/2 -> 15.948974 | R8: =P8/2 -> 8.2613391 | S8: =Q8 -> 15.948974 | T8: =R8/2 -> 4.1306695
A9: 828 | B9: 830 | C9: 70.909827 | D9: 36.717063 | E9: =C9/2 -> 35.454914 | F9: =D9/2 -> 18.358531 | G9: =E9 -> 35.454914 | H9: =F9 -> 18.358531 | I9: 0 | J9: 0 | K9: =I9/2 -> 0 | L9: =J9/2 -> 0 | M9: =K9 -> 0 | N9: =L9 -> 0 | O9: 0 | P9: 0 | Q9: =O9/2 -> 0 | R9: =P9/2 -> 0 | S9: =Q9 -> 0 | T9: =R9/2 -> 0
A10: 854 | B10: 856 | C10: 0 | D10: 0 | E10: =C10/2 -> 0 | F10: =D10/2 -> 0 | G10: =E10 -> 0 | H10: =F10 -> 0 | I10: 42.568844 | J10: 22.030238 | K10: =I10/2 -> 21.284422 | L10: =J10/2 -> 11.015119 | M10: =K10 -> 21.284422 | N10: =L10 -> 11.015119 | O10: 0 | P10: 0 | Q10: =O10/2 -> 0 | R10: =P10/2 -> 0 | S10: =Q10 -> 0 | T10: =R10/2 -> 0
A11: 832 | B11: 858 | C11: 76.646868 | D11: 39.585583 | E11: =C11/2 -> 38.323434 | F11: =D11/2 -> 19.792792 | G11: =E11 -> 38.323434 | H11: =F11 -> 19.792792 | I11: 12.392009 | J11: 6.425486 | K11: =I11/2 -> 6.1960043 | L11: =J11/2 -> 3.212743 | M11: =K11 -> 6.1960043 | N11: =L11 -> 3.212743 | O11: 61.386339 | P11: 31.783207 | Q11: =O11/2 -> 30.69317 | R11: =P11/2 -> 15.891604 | S11: =Q11 -> 30.69317 | T11: =R11/2 -> 7.9458018
A12: 858 | B12: 864 | C12: 7.2286717 | D12: 3.7864471 | E12: =C12/2 -> 3.6143359 | F12: =D12/2 -> 1.8932235 | G12: =E12 -> 3.6143359 | H12: =F12 -> 1.8932235 | I12: 0 | J12: 0 | K12: =I12/2 -> 0 | L12: =J12/2 -> 0 | M12: =K12 -> 0 | N12: =L12 -> 0 | O12: 0 | P12: 0 | Q12: =O12/2 -> 0 | R12: =P12/2 -> 0 | S12: =Q12 -> 0 | T12: =R12/2 -> 0
A13: 858 | B13: 834 | C13: 45.781587 | D13: 23.636609 | E13: =C13/2 -> 22.890794 | F13: =D13/2 -> 11.818305 | G13: =E13 -> 22.890794 | H13: =F13 -> 11.818305 | I13: 143.99973 | J13: 74.466793 | K13: =I13/2 -> 71.999865 | L13: =J13/2 -> 37.233396 | M13: =K13 -> 71.999865 | N13: =L13 -> 37.233396 | O13: 147.09773 | P13: 76.073164 | Q13: =O13/2 -> 73.548866 | R13: =P13/2 -> 38.036582 | S13: =Q13 -> 73.548866 | T13: =R13/2 -> 19.018291
... A20: 846 | B20: 848 | C20: 0 | D20: 0 | E20: =C20/2 -> 0 | F20: =D20/2 -> 0 | G20: =E20 -> 0 | H20: =F20 -> 0 | I20: 259.54374 | J20: 134.24676 | K20: =I20/2 -> 129.77187 | L20: =J20/2 -> 67.12338 | M20: =K20 -> 129.77187 | N20: =L20 -> 67.12338 | O20: 0 | P20: 0 | Q20: =O20/2 -> 0 | R20: =P20/2 -> 0 | S20: =Q20 -> 0 | T20: =R20/2 -> 0
B21: SOMA | C21: 3260.4752 | D21: 1685.4279 | I21: 2377.3151 | J21: 1228.9889 | O21: 2552.4096 | P21: 1319.6342

Sheet Planilha3
A1: Linha | B1: Fases | C1: Bus 1 | D1: Bus 2 | E1: LineCode | F1: Comprimento (mi)
A2: L1 | B2: 3 | C2: 800.1.2.3 | D2: 802.1.2.3 | E2: 300 | F2: 0.488
A3: L2 | B3: 3 | C3: 802.1.2.3 | D3: 806.1.2.3 | E3: 300 | F3: 0.32765
A4: L3 | B4: 3 | C4: 806.1.2.3 | D4: 808.1.2.3 | E4: 300 | F4: 6.1
A5: L4 | B5: 1 | C5: 808.2 | D5: 810.2 | E5: 303 | F5: 1.099
A6: L5 | B6: 3 | C6: 808.1.2.3 | D6: 812.1.2.3 | E6: 300 | F6: 7.1
A7: L6 | B7: 3 | C7: 812.1.2.3 | D7: 814.1.2.3 | E7: 300 | F7: 2.34
A8: L7 | B8: 3 | C8: 814r.1.2.3 | D8: 850.1.2.3 | E8: 301 | F8: 0.0008
A9: L8 | B9: 1 | C9: 816.1 | D9: 818.1 | E9: 302 | F9: 0.32386
A10: L9 | B10: 3 | C10: 816.1.2.3 | D10: 824.1.2.3 | E10: 301 | F10: 0.8044
A11: L10 | B11: 1 | C11: 818.1 | D11: 820.1 | E11: 302 | F11: 9.12
A12: L11 | B12: 1 | C12: 820.1 | D12: 822.1 | E12: 302 | F12: 2.6
A13: L12 | B13: 1 | C13: 824.2 | D13: 826.2 | E13: 303 | F13: 0.57386
A14: L13 | B14: 3 | C14: 824.1.2.3 | D14: 828.1.2.3 | E14: 301 | F14: 0.06104
A15: L14 | B15: 3 | C15: 828.1.2.3 | D15: 830.1.2.3 | E15: 301 | F15: 1.6104
A16: L15 | B16: 3 | C16: 830.1.2.3 | D16: 854.1.2.3 | E16: 301 | F16: 0.041
A17: L16 | B17: 3 | C17: 832.1.2.3 | D17: 858.1.2.3 | E17: 301 | F17: 0.3861
A18: L17 | B18: 3 | C18: 834.1.2.3 | D18: 860.1.2.3 | E18: 301 | F18: 0.1591
A19: L18 | B19: 3 | C19: 834.1.2.3 | D19: 842.1.2.3 | E19: 301 | F19: 0.0221
A20: L19 | B20: 3 | C20: 836.1.2.3 | D20: 840.1.2.3 | E20: 301 | F20: 0.0678
A21: L20 | B21: 3 | C21: 836.1.2.3 | D21: 862.1.2.3 | E21: 301 | F21: 0.05303
A22: L21 | B22: 3 | C22: 842.1.2.3 | D22: 844.1.2.3 | E22: 301 | F22: 0.1064
A23: L22 | B23: 3 | C23: 844.1.2.3 | D23: 846.1.2.3 | E23: 301 | F23: 0.2868
A24: L23 | B24: 3 | C24: 846.1.2.3 | D24: 848.1.2.3 | E24: 301 | F24: 0.0418
A25: L24 | B25: 3 | C25: 850.1.2.3 | D25: 816.1.2.3 | E25: 301 | F25: 0.0244
A26: L25 | B26: 3 | C26: 852r.1.2.3 | D26: 832.1.2.3 | E26: 301 | F26: 0.0008
A27: L26 | B27: 1 | C27: 854.2 | D27: 856.2 | E27: 303 | F27: 4.41856
A28: L27 | B28: 3 | C28: 854.1.2.3 | D28: 852.1.2.3 | E28: 301 | F28: 6.97537
A29: L28 | B29: 1 | C29: 858.1 | D29: 864.1 | E29: 303 | F29: 0.30681
A30: L29 | B30: 3 | C30: 858.1.2.3 | D30: 834.1.2.3 | E30: 301 | F30: 0.4593
A31: L30 | B31: 3 | C31: 860.1.2.3 | D31: 836.1.2.3 | E31: 301 | F31: 0.2111
A32: L31 | B32: 1 | C32: 862.2 | D32: 838.2 | E32: 304 | F32: 0.92045
A33: L32 | B33: 3 | C33: 888.1.2.3 | D33: 890.1.2.3 | E33: 300 | F33: 2
F34: =SUM(F2:F33) -> 49.02993

Sheet Planilha4
A1: Nome da Carga | B1: Barramento | C1: Fases | D1: Conexão | E1: Modelo | F1: kV | G1: kW | H1: kVAR
A2: S860 | B2: 860 | C2: 3 | D2: Wye | E2: 1 | F2: 24.9 | G2: 685 | H2: 549
A3: S840 | B3: 840 | C3: 3 | D3: Wye | E3: 5 | F3: 24.9 | G3: 305 | H3: 244
A4: S844 | B4: 844 | C4: 3 | D4: Wye | E4: 2 | F4: 24.9 | G4: 4593 | H4: 3677
A5: S848 | B5: 848 | C5: 3 | D5: Delta | E5: 1 | F5: 24.9 | G5: 670 | H5: 536
A6: S890 | B6: 890 | C6: 3 | D6: Delta | E6: 5 | F6: 4.16 | G6: 929 | H6: 744

Sheet Planilha6
A1: Nome da Carga | B1: Barramento | C1: Fases | D1: Conexão | E1: Modelo | F1: kV | G1: kW | H1: kVAR
A2: D802_806sb | B2: 802.2 | C2: 1 | D2: Wye | E2: 1 | F2: 14.376 | G2: 179 | H2: 93 | J2: BUS A | K2: BUS B | L2: PH-1 KW | M2: PH-1 KVAR | N2: SB KW | O2: SBKVAR | P2: RB KW | Q2: RB KVAR | R2: PH-2 KW | S2: PH-2 KVAR | T2: SB KW | U2: SBKVAR | V2: RB KW | W2: RB KVAR | X2: PH-3 KW | Y2: PH-3 KVAR | Z2: SB KW | AA2: SBKVAR | AB2: RB KW | AC2: RB KVAR
A3: D802_806rb | B3: 806.2 | C3: 1 | D3: Wye | E3: 1 | F3: 14.376 | G3: 179 | H3: 93 | J3: 802 | K3: 806 | L3: 0 | M3: 0 | N3: =L3/2 -> 0 | O3: =M3/2 -> 0 | P3: =N3 -> 0 | Q3: =O3 -> 0 | R3: 358.22084 | S3: 185.19168 | T3: =R3/2 -> 179.11042 | U3: =S3/2 -> 92.595842 | V3: =T3 -> 179.11042 | W3: =U3 -> 92.595842 | X3: 299.12932 | Y3: 154.67063 | Z3: =X3/2 -> 149.56466 | AA3: =Y3/2 -> 77.335313 | AB3: =Z3 -> 149.56466 | AC3: =AA3 -> 77.335313
A4: D802_806sc | B4: 802.3 | C4: 1 | D4: Wye | E4: 1 | F4: 14.376 | G4: 149.6 | H4: 77.3 | J4: 808 | K4: 810 | L4: 0 | M4: 0 | N4: =L4/2 -> 0 | O4: =M4/2 -> 0 | P4: =N4 -> 0 | Q4: =O4 -> 0 | R4: 182.20842 | S4: 94.202214 | T4: =R4/2 -> 91.104212 | U4: =S4/2 -> 47.101107 | V4: =T4 -> 91.104212 | W4: =U4 -> 47.101107 | X4: 0 | Y4: 0 | Z4: =X4/2 -> 0 | AA4: =Y4/2 -> 0 | AB4: =Z4 -> 0 | AC4: =AA4/2 -> 0
A5: D802_806rc | B5: 806.3 | C5: 1 | D5: Wye | E5: 1 | F5: 14.376 | G5: 149.6 | H5: 38.7 | J5: 818 | K5: 820 | L5: 388.97138 | M5: 201.02592 | N5: =L5/2 -> 194.48569 | O5: =M5/2 -> 100.51296 | P5: =N5 -> 194.48569 | Q5: =O5 -> 100.51296 | R5: 0 | S5: 0 | T5: =R5/2 -> 0 | U5: =S5/2 -> 0 | V5: =T5 -> 0 | W5: =U5 -> 0 | X5: 0 | Y5: 0 | Z5: =X5/2 -> 0 | AA5: =Y5/2 -> 0 | AB5: =Z5 -> 0 | AC5: =AA5/2 -> 0
A6: D808_810sb | B6: 808.2 | C6: 1 | D6: Wye | E6: 4 | F6: 14.376 | G6: 91 | H6: 47 | J6: 820 | K6: 822 | L6: 1555.0823 | M6: 803.98893 | N6: =L6/2 -> 777.54117 | O6: =M6/2 -> 401.99447 | P6: =N6 -> 777.54117 | Q6: =O6 -> 401.99447 | R6: 0 | S6: 0 | T6: =R6/2 -> 0 | U6: =S6/2 -> 0 | V6: =T6 -> 0 | W6: =U6 -> 0 | X6: 0 | Y6: 0 | Z6: =X6/2 -> 0 | AA6: =Y6/2 -> 0 | AB6: =Z6 -> 0 | AC6: =AA6/2 -> 0
A7: D808_810rb | B7: 810.2 | C7: 1 | D7: Wye | E7: 4 | F7: 14.376 | G7: 91 | H7: 47 | J7: 816 | K7: 824 | L7: 0 | M7: 0 | N7: =L7/2 -> 0 | O7: =M7/2 -> 0 | P7: =N7 -> 0 | Q7: =O7 -> 0 | R7: 4.474892 | S7: 2.2948164 | T7: =R7/2 -> 2.237446 | U7: =S7/2 -> 1.1474082 | V7: =T7 -> 2.237446 | W7: =U7 -> 1.1474082 | X7: 0 | Y7: 0 | Z7: =X7/2 -> 0 | AA7: =Y7/2 -> 0 | AB7: =Z7 -> 0 | AC7: =AA7/2 -> 0
A8: D818_820sa | B8: 818.1 | C8: 1 | D8: Wye | E8: 2 | F8: 14.376 | G8: 194 | H8: 101 | J8: 824 | K8: 826 | L8: 0 | M8: 0 | N8: =L8/2 -> 0 | O8: =M8/2 -> 0 | P8: =N8 -> 0 | Q8: =O8 -> 0 | R8: 481.10826 | S8: 248.7581 | T8: =R8/2 -> 240.55413 | U8: =S8/2 -> 124.37905 | V8: =T8 -> 240.55413 | W8: =U8 -> 124.37905 | X8: 0 | Y8: 0 | Z8: =X8/2 -> 0 | AA8: =Y8/2 -> 0 | AB8: =Z8 -> 0 | AC8: =AA8/2 -> 0
A9: D818_820ra | B9: 820.1 | C9: 1 | D9: Wye | E9: 2 | F9: 14.376 | G9: 194 | H9: 101 | J9: 824 | K9: 828 | L9: 0 | M9: 0 | N9: =L9/2 -> 0 | O9: =M9/2 -> 0 | P9: =N9 -> 0 | Q9: =O9 -> 0 | R9: 0 | S9: 0 | T9: =R9/2 -> 0 | U9: =S9/2 -> 0 | V9: =T9 -> 0 | W9: =U9 -> 0 | X9: 31.897948 | Y9: 16.522678 | Z9: =X9/2 -> 15.948974 | AA9: =Y9/2 -> 8.2613391 | AB9: =Z9 -> 15.948974 | AC9: =AA9 -> 8.2613391
A10: D820_822sa | B10: 820.1 | C10: 1 | D10: Wye | E10: 1 | F10: 14.376 | G10: 778 | H10: 402 | J10: 828 | K10: 830 | L10: 70.909827 | M10: 36.717063 | N10: =L10/2 -> 35.454914 | O10: =M10/2 -> 18.358531 | P10: =N10 -> 35.454914 | Q10: =O10 -> 18.358531 | R10: 0 | S10: 0 | T10: =R10/2 -> 0 | U10: =S10/2 -> 0 | V10: =T10 -> 0 | W10: =U10 -> 0 | X10: 0 | Y10: 0 | Z10: =X10/2 -> 0 | AA10: =Y10/2 -> 0 | AB10: =Z10 -> 0 | AC10: =AA10/2 -> 0
A11: D820_822ra | B11: 822.1 | C11: 1 | D11: Wye | E11: 1 | F11: 14.376 | G11: 778 | H11: 402 | J11: 854 | K11: 856 | L11: 0 | M11: 0 | N11: =L11/2 -> 0 | O11: =M11/2 -> 0 | P11: =N11 -> 0 | Q11: =O11 -> 0 | R11: 42.568844 | S11: 22.030238 | T11: =R11/2 -> 21.284422 | U11: =S11/2 -> 11.015119 | V11: =T11 -> 21.284422 | W11: =U11 -> 11.015119 | X11: 0 | Y11: 0 | Z11: =X11/2 -> 0 | AA11: =Y11/2 -> 0 | AB11: =Z11 -> 0 | AC11: =AA11/2 -> 0
A12: D816_824sb | B12: 816.2 | C12: 1 | D12: Wye | E12: 5 | F12: 14.376 | G12: 2 | H12: 1 | J12: 832 | K12: 858 | L12: 76.646868 | M12: 39.585583 | N12: =L12/2 -> 38.323434 | O12: =M12/2 -> 19.792792 | P12: =N12 -> 38.323434 | Q12: =O12 -> 19.792792 | R12: 12.392009 | S12: 6.425486 | T12: =R12/2 -> 6.1960043 | U12: =S12/2 -> 3.212743 | V12: =T12 -> 6.1960043 | W12: =U12 -> 3.212743 | X12: 61.386339 | Y12: 31.783207 | Z12: =X12/2 -> 30.69317 | AA12: =Y12/2 -> 15.891604 | AB12: =Z12 -> 30.69317 | AC12: =AA12/2 -> 7.9458018
A13: D816_824rb | B13: 824.2 | C13: 1 | D13: Wye | E13: 5 | F13: 14.376 | G13: 2 | H13: 1 | J13: 858 | K13: 864 | L13: 7.2286717 | M13: 3.7864471 | N13: =L13/2 -> 3.6143359 | O13: =M13/2 -> 1.8932235 | P13: =N13 -> 3.6143359 | Q13: =O13 -> 1.8932235 | R13: 0 | S13: 0 | T13: =R13/2 -> 0 | U13: =S13/2 -> 0 | V13: =T13 -> 0 | W13: =U13 -> 0 | X13: 0 | Y13: 0 | Z13: =X13/2 -> 0 | AA13: =Y13/2 -> 0 | AB13: =Z13 -> 0 | AC13: =AA13/2 -> 0
A14: D824_826sb | B14: 824.2 | C14: 1 | D14: Wye | E14: 5 | F14: 14.376 | G14: 241 | H14: 124 | J14: 858 | K14: 834 | L14: 45.781587 | M14: 23.636609 | N14: =L14/2 -> 22.890794 | O14: =M14/2 -> 11.818305 | P14: =N14 -> 22.890794 | Q14: =O14 -> 11.818305 | R14: 143.99973 | S14: 74.466793 | T14: =R14/2 -> 71.999865 | U14: =S14/2 -> 37.233396 | V14: =T14 -> 71.999865 | W14: =U14 -> 37.233396 | X14: 147.09773 | Y14: 76.073164 | Z14: =X14/2 -> 73.548866 | AA14: =Y14/2 -> 38.036582 | AB14: =Z14 -> 73.548866 | AC14: =AA14/2 -> 19.018291
A15: D824_826rb | B15: 826.2 | C15: 1 | D15: Wye | E15: 5 | F15: 14.376 | G15: 241 | H15: 124 | J15: 834 | K15: 860 | L15: 179.68413 | M15: 92.825324 | N15: =L15/2 -> 89.842063 | O15: =M15/2 -> 46.412662 | P15: =N15 -> 89.842063 | Q15: =O15 -> 46.412662 | R15: 239.34935 | S15: 123.6906 | T15: =R15/2 -> 119.67468 | U15: =S15/2 -> 61.845302 | V15: =T15 -> 119.67468 | W15: =U15 -> 61.845302 | X15: 1275.3442 | Y15: 659.30076 | Z15: =X15/2 -> 637.67211 | AA15: =Y15/2 -> 329.65038 | AB15: =Z15 -> 637.67211 | AC15: =AA15 -> 329.65038
A16: D824_828sc | B16: 824.3 | C16: 1 | D16: Wye | E16: 1 | F16: 14.376 | G16: 15.9 | H16: 8.3 | J16: 860 | K16: 836 | L16: 314.04563 | M16: 162.35826 | N16: =L16/2 -> 157.02281 | O16: =M16/2 -> 81.179131 | P16: =N16 -> 157.02281 | Q16: =O16 -> 81.179131 | R16: 121.05157 | S16: 62.533747 | T16: =R16/2 -> 60.525783 | U16: =S16/2 -> 31.266874 | V16: =T16 -> 60.525783 | W16: =U16 -> 31.266874 | X16: 482.48515 | Y16: 249.44654 | Z16: =X16/2 -> 241.24258 | AA16: =Y16/2 -> 124.72327 | AB16: =Z16 -> 241.24258 | AC16: =AA16/2 -> 62.361636
A17: D824_828rc | B17: 828.3 | C17: 1 | D17: Wye | E17: 1 | F17: 14.376 | G17: 15.9 | H17: 4.1 | J17: 836 | K17: 840 | L17: 200.6817 | M17: 103.7257 | N17: =L17/2 -> 100.34085 | O17: =M17/2 -> 51.862851 | P17: =N17 -> 100.34085 | Q17: =O17 -> 51.862851 | R17: 250.24973 | S17: 129.3129 | T17: =R17/2 -> 125.12487 | U17: =S17/2 -> 64.656452 | V17: =T17 -> 125.12487 | W17: =U17 -> 64.656452 | X17: 0 | Y17: 0 | Z17: =X17/2 -> 0 | AA17: =Y17/2 -> 0 | AB17: =Z17 -> 0 | AC17: =AA17/2 -> 0
A18: D828_830sa | B18: 828.1 | C18: 1 | D18: Wye | E18: 1 | F18: 14.376 | G18: 35 | H18: 18 | J18: 862 | K18: 838 | L18: 316.79941 | M18: 163.73515 | N18: =L18/2 -> 158.3997 | O18: =M18/2 -> 81.867576 | P18: =N18 -> 158.3997 | Q18: =O18 -> 81.867576 | R18: 0 | S18: 0 | T18: =R18/2 -> 0 | U18: =S18/2 -> 0 | V18: =T18 -> 0 | W18: =U18 -> 0 | X18: 0 | Y18: 0 | Z18: =X18/2 -> 0 | AA18: =Y18/2 -> 0 | AB18: =Z18 -> 0 | AC18: =AA18/2 -> 0
A19: D828_830ra | B19: 830.1 | C19: 1 | D19: Wye | E19: 1 | F19: 14.376 | G19: 35 | H19: 18 | J19: 842 | K19: 844 | L19: 104.64363 | M19: 54.042927 | N19: =L19/2 -> 52.321814 | O19: =M19/2 -> 27.021463 | P19: =N19 -> 52.321814 | Q19: =O19 -> 27.021463 | R19: 0 | S19: 0 | T19: =R19/2 -> 0 | U19: =S19/2 -> 0 | V19: =T19 -> 0 | W19: =U19 -> 0 | X19: 0 | Y19: 0 | Z19: =X19/2 -> 0 | AA19: =Y19/2 -> 0 | AB19: =Z19 -> 0 | AC19: =AA19/2 -> 0
A20: D854_856sb | B20: 854.2 | C20: 1 | D20: Wye | E20: 1 | F20: 14.376 | G20: 21 | H20: 11 | J20: 844 | K20: 846 | L20: 0 | M20: 0 | N20: =L20/2 -> 0 | O20: =M20/2 -> 0 | P20: =N20 -> 0 | Q20: =O20 -> 0 | R20: 282.14768 | S20: 145.83558 | T20: =R20/2 -> 141.07384 | U20: =S20/2 -> 72.917792 | V20: =T20 -> 141.07384 | W20: =U20 -> 72.917792 | X20: 255.06884 | Y20: 131.8372 | Z20: =X20/2 -> 127.53442 | AA20: =Y20/2 -> 65.918602 | AB20: =Z20 -> 127.53442 | AC20: =AA20/2 -> 32.959301
A21: D854_856rb | B21: 856.2 | C21: 1 | D21: Wye | E21: 1 | F21: 14.376 | G21: 21 | H21: 11 | J21: 846 | K21: 848 | L21: 0 | M21: 0 | N21: =L21/2 -> 0 | O21: =M21/2 -> 0 | P21: =N21 -> 0 | Q21: =O21 -> 0 | R21: 259.54374 | S21: 134.24676 | T21: =R21/2 -> 129.77187 | U21: =S21/2 -> 67.12338 | V21: =T21 -> 129.77187 | W21: =U21 -> 67.12338 | X21: 0 | Y21: 0 | Z21: =X21/2 -> 0 | AA21: =Y21/2 -> 0 | AB21: =Z21 -> 0 | AC21: =AA21/2 -> 0
A22: D832_858sa | B22: 832.1 | C22: 1 | D22: Wye | E22: 2 | F22: 14.376 | G22: 38 | H22: 20 | K22: SOMA | L22: 3260.4752 | M22: 1685.4279 | R22: 2377.3151 | S22: 1228.9889 | X22: 2552.4096 | Y22: 1319.6342
A23: D832_858ra | B23: 858.1 | C23: 1 | D23: Wye | E23: 2 | F23: 14.376 | G23: 38 | H23: 20
A24: D832_858sb | B24: 832.2 | C24: 1 | D24: Wye | E24: 2 | F24: 14.376 | G24: 6 | H24: 3
A25: D832_858rb | B25: 858.2 | C25: 1 | D25: Wye | E25: 2 | F25: 14.376 | G25: 6 | H25: 3
A26: D832_858sc | B26: 832.3 | C26: 1 | D26: Wye | E26: 2 | F26: 14.376 | G26: 30.7 | H26: 15.9
A27: D832_858rc | B27: 858.3 | C27: 1 | D27: Wye | E27: 2 | F27: 14.376 | G27: 30.7 | H27: 7.9
A28: D858_864sb | B28: 858.1 | C28: 1 | D28: Wye | E28: 1 | F28: 14.376 | G28: 4 | H28: 2
A29: D858_864rb | B29: 864.1 | C29: 1 | D29: Wye | E29: 1 | F29: 14.376 | G29: 4 | H29: 2
A30: D858_834sa | B30: 858.1 | C30: 1 | D30: Wye | E30: 1 | F30: 14.376 | G30: 23 | H30: 12
A31: D858_834ra | B31: 834.1 | C31: 1 | D31: Wye | E31: 1 | F31: 14.376 | G31: 23 | H31: 12
A32: D858_834sb | B32: 858.2 | C32: 1 | D32: Wye | E32: 1 | F32: 14.376 | G32: 72 | H32: 37
A33: D858_834rb | B33: 834.2 | C33: 1 | D33: Wye | E33: 1 | F33: 14.376 | G33: 72 | H33: 37
A34: D858_834sc | B34: 858.3 | C34: 1 | D34: Wye | E34: 1 | F34: 14.376 | G34: 73.5 | H34: 38
... A61: D846_848rb | B61: 848.2 | C61: 1 | D61: Wye | E61: 1 | F61: 14.376 | G61: 130 | H61: 67
